Workbook

Sheet Needs Assessment
A1: ONYX ACCOUNTING GROUP — CLIENT NEEDS ASSESSMENT
A2: How to use: 1) During the meeting, glance down the list to make sure every area is discussed — no need to type. 2) After the call, paste the transcript into the Transcript tab. 3) The “In transcript?” column auto-flags topics that came up; fill Yes/No + Notes from there.
A3: Assessment category | B3: Yes / No | C3: Notes / Advisories | D3: Help resources | E3: In transcript? | F3: keyword(helper)
A4: Sales and accounts receivable
A5: Estimates | D5: When to use Estimates | E5: =IF($F5="","",IF(COUNTIF(Transcript!$A$4:$A$5000,"*"&$F5&"*")>0,"✓ mentioned","")) | F5: estimate
A6: Simple invoices (no customer tracking) | D6: Simple invoicing in QuickBooks Self-Employed
A7: Custom invoices (accounts receivable tracking) | D7: When to use Invoices
A8: Sales receipts | D8: When to use Sales Receipts | E8: =IF($F8="","",IF(COUNTIF(Transcript!$A$4:$A$5000,"*"&$F8&"*")>0,"✓ mentioned","")) | F8: sales receipt
A9: Statements | D9: When to use Statements
A10: Sales tax (list states in notes/advisory column) | D10: How to set up Sales Tax | E10: =IF($F10="","",IF(COUNTIF(Transcript!$A$4:$A$5000,"*"&$F10&"*")>0,"✓ mentioned","")) | F10: sales tax
A11: Price levels | D11: When to use Price Rules | E11: =IF($F11="","",IF(COUNTIF(Transcript!$A$4:$A$5000,"*"&$F11&"*")>0,"✓ mentioned","")) | F11: price level
A12: Progress invoicing | D12: When to use Progress Invoicing | E12: =IF($F12="","",IF(COUNTIF(Transcript!$A$4:$A$5000,"*"&$F12&"*")>0,"✓ mentioned","")) | F12: progress invoic
A13: Multicurrency | D13: Understanding Multicurrency | E13: =IF($F13="","",IF(COUNTIF(Transcript!$A$4:$A$5000,"*"&$F13&"*")>0,"✓ mentioned","")) | F13: currenc
A14: Average number of transactions per month
A15: Expenses and accounts payable
A16: Accrual-based (bills and bill payments) | D16: When to use bills, checks, and expenses | E16: =IF($F16="","",IF(COUNTIF(Transcript!$A$4:$A$5000,"*"&$F16&"*")>0,"✓ mentioned","")) | F16: accrual
A17: Approvals | D17: Apps to manage Accounts Payable Approvals | E17: =IF($F17="","",IF(COUNTIF(Transcript!$A$4:$A$5000,"*"&$F17&"*")>0,"✓ mentioned","")) | F17: approval
A18: Checks (indicate manual, printed, or both in notes/advisory column) | D18: How to write a check | E18: =IF($F18="","",IF(COUNTIF(Transcript!$A$4:$A$5000,"*"&$F18&"*")>0,"✓ mentioned","")) | F18: check
A19: Credit card expenses | D19: Record an expense | E19: =IF($F19="","",IF(COUNTIF(Transcript!$A$4:$A$5000,"*"&$F19&"*")>0,"✓ mentioned","")) | F19: credit card
A20: Electronic payments | D20: Bill Pay in QuickBooks Online
A21: Loans (list types in notes/advisory column) | D21: How to record a loan and its payment | E21: =IF($F21="","",IF(COUNTIF(Transcript!$A$4:$A$5000,"*"&$F21&"*")>0,"✓ mentioned","")) | F21: loan
A22: Multicurrency | D22: About multicurrency in QuickBooks | E22: =IF($F22="","",IF(COUNTIF(Transcript!$A$4:$A$5000,"*"&$F22&"*")>0,"✓ mentioned","")) | F22: currenc
A23: Separation of personal and business expenses in same bank/credit card account | D23: Separating personal from business finance | E23: =IF($F23="","",IF(COUNTIF(Transcript!$A$4:$A$5000,"*"&$F23&"*")>0,"✓ mentioned","")) | F23: personal
A24: Petty cash expenses | D24: Set up and track Petty Cash | E24: =IF($F24="","",IF(COUNTIF(Transcript!$A$4:$A$5000,"*"&$F24&"*")>0,"✓ mentioned","")) | F24: petty cash
A25: Purchase orders | D25: How to use a Purchase Order | E25: =IF($F25="","",IF(COUNTIF(Transcript!$A$4:$A$5000,"*"&$F25&"*")>0,"✓ mentioned","")) | F25: purchase order
A26: Track vendors for 1099 reporting | D26: How to track 1099 Contractors | E26: =IF($F26="","",IF(COUNTIF(Transcript!$A$4:$A$5000,"*"&$F26&"*")>0,"✓ mentioned","")) | F26: 1099
A27: Billable/Reimbursable expenses | D27: How to enter billable expenses | E27: =IF($F27="","",IF(COUNTIF(Transcript!$A$4:$A$5000,"*"&$F27&"*")>0,"✓ mentioned","")) | F27: reimburs
A28: Electronic receipt/bill capture | D28: How to use Receipt Capture | E28: =IF($F28="","",IF(COUNTIF(Transcript!$A$4:$A$5000,"*"&$F28&"*")>0,"✓ mentioned","")) | F28: receipt
A29: Average number of transactions per month
A30: Employees and payroll
A31: Active workers’ compensation insurance | D31: Learn about workers’ comp insurance | E31: =IF($F31="","",IF(COUNTIF(Transcript!$A$4:$A$5000,"*"&$F31&"*")>0,"✓ mentioned","")) | F31: workers
A32: Number of employees on payroll
A33: Partners/Shareholders on payroll | E33: =IF($F33="","",IF(COUNTIF(Transcript!$A$4:$A$5000,"*"&$F33&"*")>0,"✓ mentioned","")) | F33: shareholder
A34: PTO/Sick/Vacation policy | D34: Add vacation or sick leave policies | E34: =IF($F34="","",IF(COUNTIF(Transcript!$A$4:$A$5000,"*"&$F34&"*")>0,"✓ mentioned","")) | F34: vacation
A35: Retirement plan | D35: Set up retirement deductions and contributions | E35: =IF($F35="","",IF(COUNTIF(Transcript!$A$4:$A$5000,"*"&$F35&"*")>0,"✓ mentioned","")) | F35: retirement
A36: Time tracking (indicate vendors, employees, or both in notes/advisory column) | D36: How to turn on and set up time tracking | E36: =IF($F36="","",IF(COUNTIF(Transcript!$A$4:$A$5000,"*"&$F36&"*")>0,"✓ mentioned","")) | F36: time tracking
A37: Average number of transactions per month
A38: Other expense-tracking needs
A39: Estimated income taxes | D39: Quarterly Estimated Taxes Explained | E39: =IF($F39="","",IF(COUNTIF(Transcript!$A$4:$A$5000,"*"&$F39&"*")>0,"✓ mentioned","")) | F39: estimated tax
A40: Mileage tracking—if yes, then complete the vehicle profile on the Mileage tab | D40: What Is Mileage Tracking? | E40: =IF($F40="","",IF(COUNTIF(Transcript!$A$4:$A$5000,"*"&$F40&"*")>0,"✓ mentioned","")) | F40: mileage
...

Sheet Transcript
A1: MEETING TRANSCRIPT
A2: Paste the full meeting transcript below, starting in cell A4 (Ctrl+V). It is fine if it splits across many rows — the Needs Assessment tab scans all of it.
